Workbook

Sheet README
A1: Mortgage Servicing Migration - Metadata & Data Mapping Workbook
A2: Spreadsheet-based metadata repository for migration mapping, controls, rules, reconciliation, and signoff.
A4: Section | B4: Purpose | C4: How to Use
A5: Source System Inventory | B5: Documents legacy and target systems, feeds, reports, and owners. | C5: Identify applications, data stores, extracts, interfaces, reports, and downstream consumers.
A6: Source Data Dictionary | B6: Captures physical source metadata and business meaning. | C6: Populate field-level metadata from the legacy servicing platform and related systems.
A7: Target Data Dictionary | B7: Captures target entities, fields, constraints, and allowed values. | C7: Use target vendor/API/data model documentation to populate required fields.
A8: Business Glossary | B8: Standardizes mortgage servicing terms. | C8: Resolve conflicting meanings such as UPB, due date, delinquency status, and suspense.
A9: Critical Data Elements | B9: Prioritizes high-risk fields for stronger controls. | C9: Classify by criticality, sensitivity, regulatory impact, DQ, and reconciliation needs.
A10: Source-to-Target Mapping | B10: Core field-level mapping matrix. | C10: Link each mapping row to transformation, DQ, reconciliation, issue, and signoff evidence.
A11: Transformation Rules | B11: Documents conversion logic. | C11: Create reusable rule IDs for calculations, lookups, defaults, and survivorship.
A12: Code Lookup Crosswalk | B12: Maps legacy values to target values. | C12: Use for payment, default, delinquency, investor, escrow, and fee codes.
A13: Data Quality Rules | B13: Defines validation checks. | C13: Document required, format, range, valid value, uniqueness, and balance checks.
A14: Reconciliation Rules | B14: Defines migration proof points. | C14: Use counts, balances, payment totals, escrow totals, and status tie-outs.
A15: Issues Decisions Log | B15: Tracks open questions, decisions, assumptions, and risks. | C15: Log business rationale and approval; do not bury decisions in email.
A16: Signoff Tracker | B16: Tracks approvals and conditions. | C16: Use for readiness reporting and cutover evidence.

Sheet Dashboard
A1: Metadata & Data Mapping Dashboard
A2: Summary view for mapping progress, critical fields, approvals, issues, and readiness.
A4: Metric | B4: Value | C4: Formula / Source | E4: Data Domain | F4: Total Mappings | G4: Approved | H4: Implemented | I4: Tested | J4: Open
A5: Total Mappings | B5: =COUNTA('Source-to-Target Mapping'!A5:A104) -> 32 | C5: Count of mapping IDs | E5: Loan | F5: =COUNTIF('Source-to-Target Mapping'!N5:N104,E5) -> 6 | G5: =COUNTIFS('Source-to-Target Mapping'!N5:N104,E5,'Source-to-Target Mapping'!Q5:Q104,"Approved") -> 5 | H5: =COUNTIFS('Source-to-Target Mapping'!N5:N104,E5,'Source-to-Target Mapping'!Q5:Q104,"Implemented") -> 0 | I5: =COUNTIFS('Source-to-Target Mapping'!N5:N104,E5,'Source-to-Target Mapping'!Q5:Q104,"Tested") -> 0 | J5: =F5-G5-H5-I5 -> 1
A6: Approved Mappings | B6: =COUNTIF('Source-to-Target Mapping'!Q5:Q104,"Approved") -> 25 | C6: Status = Approved | E6: Borrower | F6: =COUNTIF('Source-to-Target Mapping'!N5:N104,E6) -> 0 | G6: =COUNTIFS('Source-to-Target Mapping'!N5:N104,E6,'Source-to-Target Mapping'!Q5:Q104,"Approved") -> 0 | H6: =COUNTIFS('Source-to-Target Mapping'!N5:N104,E6,'Source-to-Target Mapping'!Q5:Q104,"Implemented") -> 0 | I6: =COUNTIFS('Source-to-Target Mapping'!N5:N104,E6,'Source-to-Target Mapping'!Q5:Q104,"Tested") -> 0 | J6: =F6-G6-H6-I6 -> 0
A7: Implemented Mappings | B7: =COUNTIF('Source-to-Target Mapping'!Q5:Q104,"Implemented") -> 0 | C7: Status = Implemented | E7: Property | F7: =COUNTIF('Source-to-Target Mapping'!N5:N104,E7) -> 6 | G7: =COUNTIFS('Source-to-Target Mapping'!N5:N104,E7,'Source-to-Target Mapping'!Q5:Q104,"Approved") -> 6 | H7: =COUNTIFS('Source-to-Target Mapping'!N5:N104,E7,'Source-to-Target Mapping'!Q5:Q104,"Implemented") -> 0 | I7: =COUNTIFS('Source-to-Target Mapping'!N5:N104,E7,'Source-to-Target Mapping'!Q5:Q104,"Tested") -> 0 | J7: =F7-G7-H7-I7 -> 0
A8: Tested Mappings | B8: =COUNTIF('Source-to-Target Mapping'!Q5:Q104,"Tested") -> 0 | C8: Status = Tested | E8: Payment | F8: =COUNTIF('Source-to-Target Mapping'!N5:N104,E8) -> 5 | G8: =COUNTIFS('Source-to-Target Mapping'!N5:N104,E8,'Source-to-Target Mapping'!Q5:Q104,"Approved") -> 4 | H8: =COUNTIFS('Source-to-Target Mapping'!N5:N104,E8,'Source-to-Target Mapping'!Q5:Q104,"Implemented") -> 0 | I8: =COUNTIFS('Source-to-Target Mapping'!N5:N104,E8,'Source-to-Target Mapping'!Q5:Q104,"Tested") -> 0 | J8: =F8-G8-H8-I8 -> 1
A9: Open Critical CDEs | B9: =COUNTIFS('Critical Data Elements'!G5:G104,"Tier 1",'Critical Data Elements'!L5:L104,"<>Approved",'Critical Data Elements'!L5:L104,"<>Tested")+COUNTIFS('Critical Data Elements'!G5:G104,"Tier 2",'Critical Data Elements'!L5:L104,"<>Approved",'Critical Data Elements'!L5:L104,"<>Tested") -> 4 | C9: Tier 1 or Tier 2 and status not Approved/Tested | E9: Escrow | F9: =COUNTIF('Source-to-Target Mapping'!N5:N104,E9) -> 1 | G9: =COUNTIFS('Source-to-Target Mapping'!N5:N104,E9,'Source-to-Target Mapping'!Q5:Q104,"Approved") -> 1 | H9: =COUNTIFS('Source-to-Target Mapping'!N5:N104,E9,'Source-to-Target Mapping'!Q5:Q104,"Implemented") -> 0 | I9: =COUNTIFS('Source-to-Target Mapping'!N5:N104,E9,'Source-to-Target Mapping'!Q5:Q104,"Tested") -> 0 | J9: =F9-G9-H9-I9 -> 0
A10: Open High Issues | B10: =COUNTIFS('Issues Decisions Log'!F5:F104,"High",'Issues Decisions Log'!I5:I104,"<>Closed") -> 2 | C10: Severity = High and status not Closed | E10: Investor | F10: =COUNTIF('Source-to-Target Mapping'!N5:N104,E10) -> 0 | G10: =COUNTIFS('Source-to-Target Mapping'!N5:N104,E10,'Source-to-Target Mapping'!Q5:Q104,"Approved") -> 0 | H10: =COUNTIFS('Source-to-Target Mapping'!N5:N104,E10,'Source-to-Target Mapping'!Q5:Q104,"Implemented") -> 0 | I10: =COUNTIFS('Source-to-Target Mapping'!N5:N104,E10,'Source-to-Target Mapping'!Q5:Q104,"Tested") -> 0 | J10: =F10-G10-H10-I10 -> 0
A11: Reconciliation Rules | B11: =COUNTA('Reconciliation Rules'!A5:A104) -> 7 | C11: Count of reconciliation rules | E11: Default | F11: =COUNTIF('Source-to-Target Mapping'!N5:N104,E11) -> 0 | G11: =COUNTIFS('Source-to-Target Mapping'!N5:N104,E11,'Source-to-Target Mapping'!Q5:Q104,"Approved") -> 0 | H11: =COUNTIFS('Source-to-Target Mapping'!N5:N104,E11,'Source-to-Target Mapping'!Q5:Q104,"Implemented") -> 0 | I11: =COUNTIFS('Source-to-Target Mapping'!N5:N104,E11,'Source-to-Target Mapping'!Q5:Q104,"Tested") -> 0 | J11: =F11-G11-H11-I11 -> 0
E12: Compliance | F12: =COUNTIF('Source-to-Target Mapping'!N5:N104,E12) -> 0 | G12: =COUNTIFS('Source-to-Target Mapping'!N5:N104,E12,'Source-to-Target Mapping'!Q5:Q104,"Approved") -> 0 | H12: =COUNTIFS('Source-to-Target Mapping'!N5:N104,E12,'Source-to-Target Mapping'!Q5:Q104,"Implemented") -> 0 | I12: =COUNTIFS('Source-to-Target Mapping'!N5:N104,E12,'Source-to-Target Mapping'!Q5:Q104,"Tested") -> 0 | J12: =F12-G12-H12-I12 -> 0
E13: Communication | F13: =COUNTIF('Source-to-Target Mapping'!N5:N104,E13) -> 0 | G13: =COUNTIFS('Source-to-Target Mapping'!N5:N104,E13,'Source-to-Target Mapping'!Q5:Q104,"Approved") -> 0 | H13: =COUNTIFS('Source-to-Target Mapping'!N5:N104,E13,'Source-to-Target Mapping'!Q5:Q104,"Implemented") -> 0 | I13: =COUNTIFS('Source-to-Target Mapping'!N5:N104,E13,'Source-to-Target Mapping'!Q5:Q104,"Tested") -> 0 | J13: =F13-G13-H13-I13 -> 0

Sheet Source System Inventory
A2: Inventory of source, target, supporting applications, databases, extracts, reports, and interfaces.
A4: System ID | B4: System Name | C4: System Type | D4: Business Capability | E4: Owner | F4: SME | G4: Data Store / Interface | H4: Data Sensitivity | I4: Migration Role | J4: Downstream Consumers | K4: Notes
A5: SYS-001 | B5: Legacy Servicing Platform | C5: Application/DB | D5: Core servicing | E5: Servicing Ops | F5: Sarah Kim | G5: DB tables, nightly extracts | H5: NPI | I5: Source | J5: Reporting, investor reporting, call center | K5: Primary migration source
A6: SYS-002 | B6: Payment Processor | C6: Application/API | D6: Payment processing | E6: Payment Ops | F6: Michael Chen | G6: Files/API | H6: NPI | I6: Source/Reference | J6: Servicing platform, finance | K6: Confirm payment data handling
A7: SYS-003 | B7: Document Imaging | C7: Content Repository | D7: Notices and correspondence | E7: Customer Ops | F7: Emily Davis | G7: Documents/metadata | H7: NPI | I7: Source/Archive | J7: Compliance, customer service | K7: May require metadata-only mapping
A8: SYS-004 | B8: Customer Portal | C8: Web Application | D8: Customer Self-Service | E8: Digital Banking | F8: James Patel | G8: REST API | H8: PII | I8: Source | J8: Customer Service | K8: Migrate customer preferences
A9: SYS-005 | B9: Escrow Management | C9: Application | D9: Escrow Administration | E9: Escrow Ops | F9: Jessica Lee | G9: SQL Database | H9: Financial | I9: Source | J9: Finance | K9: Validate escrow balances
A10: SYS-006 | B10: Investor Reporting | C10: Reporting Platform | D10: Investor Reporting | E10: Finance | F10: David Wilson | G10: Data Warehouse | H10: Financial | I10: Reference | J10: Investors | K10: Historical reporting data
A11: SYS-007 | B11: Loan Origination System | C11: Application | D11: Loan Origination | E11: Lending Ops | F11: Sophia Martinez | G11: Oracle Database | H11: NPI | I11: Reference | J11: Underwriting | K11: Historical loan information
A12: SYS-008 | B12: CRM Platform | C12: SaaS Application | D12: Customer Relationship Management | E12: Customer Success | F12: Ethan Walker | G12: Cloud API | H12: PII | I12: Target | J12: Customer Support | K12: Receives migrated customer records

Sheet Source Data Dictionary
A1: Source Data Dictionary
A2: Physical and business metadata for legacy servicing platform and related source data.
A4: Source Field ID | B4: Source System | C4: Database/File/API | D4: Table/Object | E4: Column/Field | F4: Business Name | G4: Business Definition | H4: Data Type | I4: Length | J4: Nullable | K4: Valid Values / Domain | L4: Sample Value | M4: Data Sensitivity | N4: Known Data Quality Notes | O4: Owner/SME
A5: SRC-0001 | B5: Legacy Servicing Platform | C5: SERVDB | D5: LOAN_MASTER | E5: LOAN_NBR | F5: Loan Number | G5: Primary servicing loan identifier | H5: VARCHAR | I5: 20 | J5: No | K5: Unique loan number | L5: 1234567890 | M5: NPI | N5: Must be unique | O5: Sarah Kim
A6: SRC-0002 | B6: Legacy Servicing Platform | C6: SERVDB | D6: LOAN_BALANCE | E6: UPB_AMT | F6: Unpaid Principal Balance | G6: Current unpaid principal balance as of processing date | H6: DECIMAL | I6: 18,2 | J6: No | K6: Positive decimal | L6: 245000 | M6: Confidential | N6: Balance must reconcile | O6: Sarah Kim
A7: SRC-0003 | B7: Legacy Servicing Platform | C7: SERVDB | D7: PAYMENT_TXN | E7: TXN_CD | F7: Payment Transaction Code | G7: Legacy code representing payment transaction type | H7: VARCHAR | I7: 10 | J7: No | K7: See code crosswalk | L7: PMT | M7: Internal | N7: Requires target value mapping | O7: Michael Chen
A8: SRC-0004 | B8: Legacy Servicing Platform | C8: SERVDB | D8: CUSTOMER | E8: CUST_ID | F8: Customer ID | G8: Unique customer identifier in legacy system | H8: VARCHAR | I8: 15 | J8: No | K8: Unique customer ID | L8: C100234 | M8: NPI | N8: Check for duplicate IDs | O8: Sarah Kim
A9: SRC-0005 | B9: Legacy Servicing Platform | C9: SERVDB | D9: CUSTOMER | E9: FIRST_NAME | F9: First Name | G9: Customer legal first name | H9: VARCHAR | I9: 50 | J9: No | K9: Alphabetic | L9: John | M9: PII | N9: Trim extra spaces | O9: Sarah Kim
A10: SRC-0006 | B10: Legacy Servicing Platform | C10: SERVDB | D10: CUSTOMER | E10: LAST_NAME | F10: Last Name | G10: Customer legal last name | H10: VARCHAR | I10: 50 | J10: No | K10: Alphabetic | L10: Smith | M10: PII | N10: Trim extra spaces | O10: Sarah Kim
A11: SRC-0007 | B11: Legacy Servicing Platform | C11: SERVDB | D11: CUSTOMER | E11: DOB | F11: Date of Birth | G11: Customer date of birth | H11: DATE | I11: 10 | J11: Yes | K11: Valid date | L11: 31240 | M11: PII | N11: Some invalid dates found | O11: Sarah Kim
A12: SRC-0008 | B12: Legacy Servicing Platform | C12: SERVDB | D12: CUSTOMER | E12: EMAIL | F12: Email Address | G12: Customer email address | H12: VARCHAR | I12: 100 | J12: Yes | K12: Valid email format | L12: john.email.com | M12: PII | N12: Invalid email format example | O12: Sarah Kim
A13: SRC-0009 | B13: Legacy Servicing Platform | C13: SERVDB | D13: CUSTOMER | E13: PHONE | F13: Phone Number | G13: Primary customer phone number | H13: VARCHAR | I13: 15 | J13: Yes | K13: Phone number format | L13: 9725551234 | M13: PII | N13: Inconsistent formatting | O13: Sarah Kim
A14: SRC-0010 | B14: Legacy Servicing Platform | C14: SERVDB | D14: LOAN_MASTER | E14: LOAN_STATUS | F14: Loan Status | G14: Current servicing status of the loan | H14: VARCHAR | I14: 20 | J14: No | K14: Active, Closed, Delinquent | L14: A | M14: Internal | N14: Legacy status codes inconsistent | O14: Sarah Kim
A15: SRC-0011 | B15: Legacy Servicing Platform | C15: SERVDB | D15: LOAN_MASTER | E15: INTEREST_RATE | F15: Interest Rate | G15: Current loan interest rate | H15: DECIMAL | I15: 5,2 | J15: No | K15: Positive decimal | L15: 5.25 | M15: Financial | N15: Validate precision | O15: Sarah Kim
A16: SRC-0012 | B16: Legacy Servicing Platform | C16: SERVDB | D16: ESCROW | E16: ESCROW_BAL | F16: Escrow Balance | G16: Current escrow account balance | H16: DECIMAL | I16: 18,2 | J16: Yes | K16: Positive decimal | L16: 3200.75 | M16: Financial | N16: Reconcile with escrow records | O16: Jessica Lee
A17: SRC-0013 | B17: Legacy Servicing Platform | C17: SERVDB | D17: PROPERTY | E17: PROPERTY_ADDR | F17: Property Address | G17: Street address of secured property | H17: VARCHAR | I17: 100 | J17: No | K17: Valid address | L17: 123 Main St | M17: PII | N17: Standardize abbreviations | O17: James Patel
A18: SRC-0014 | B18: Legacy Servicing Platform | C18: SERVDB | D18: PROPERTY | E18: CITY | F18: Property City | G18: Property city name | H18: VARCHAR | I18: 50 | J18: No | K18: City name | L18: Dallas | M18: Internal | N18: Standardize capitalization | O18: James Patel
A19: SRC-0015 | B19: Legacy Servicing Platform | C19: SERVDB | D19: PROPERTY | E19: STATE | F19: Property State | G19: Property state abbreviation | H19: VARCHAR | I19: 2 | J19: No | K19: US state code | L19: Texas | M19: Internal | N19: Should be 2-letter state code | O19: James Patel
A20: SRC-0016 | B20: Legacy Servicing Platform | C20: SERVDB | D20: PROPERTY | E20: ZIP_CODE | F20: ZIP Code | G20: Property postal ZIP code | H20: VARCHAR | I20: 10 | J20: No | K20: Valid ZIP code | L20: 75070 | M20: Internal | N20: Check ZIP length | O20: James Patel
A21: SRC-0017 | B21: Payment Processor | C21: PAYMENT_API | D21: PAYMENT_TXN | E21: PAYMENT_DATE | F21: Payment Date | G21: Date payment was received | H21: DATE | I21: 10 | J21: No | K21: Valid date | L21: 46037 | M21: Financial | N21: Must not be future date | O21: Michael Chen
A22: SRC-0018 | B22: Payment Processor | C22: PAYMENT_API | D22: PAYMENT_TXN | E22: PAYMENT_AMT | F22: Payment Amount | G22: Amount of payment received | H22: DECIMAL | I22: 18,2 | J22: No | K22: Positive decimal | L22: 1500 | M22: Financial | N22: Must tie to payment totals | O22: Michael Chen
A23: SRC-0019 | B23: Payment Processor | C23: PAYMENT_API | D23: PAYMENT_TXN | E23: PAYMENT_METHOD | F23: Payment Method | G23: Method used by borrower to submit payment | H23: VARCHAR | I23: 20 | J23: Yes | K23: ACH, Check, Card | L23: ACH | M23: Internal | N23: Requires standard values | O23: Michael Chen
A24: SRC-0020 | B24: Payment Processor | C24: PAYMENT_API | D24: PAYMENT_TXN | E24: REVERSAL_IND | F24: Reversal Indicator | G24: Indicates whether payment was reversed | H24: VARCHAR | I24: 1 | J24: No | K24: Y or N | L24: N | M24: Internal | N24: Validate allowed values | O24: Michael Chen
A25: SRC-0021 | B25: Document Imaging | C25: DOC_REPO | D25: DOCUMENT | E25: DOC_ID | F25: Document ID | G25: Unique document identifier | H25: VARCHAR | I25: 30 | J25: No | K25: Unique document ID | L25: DOC78901 | M25: NPI | N25: Must link to metadata | O25: Emily Davis
A26: SRC-0022 | B26: Document Imaging | C26: DOC_REPO | D26: DOCUMENT | E26: DOC_TYPE | F26: Document Type | G26: Type of borrower document | H26: VARCHAR | I26: 30 | J26: No | K26: Statement, Notice, Letter | L26: Notice | M26: Internal | N26: Requires document type mapping | O26: Emily Davis
A27: SRC-0023 | B27: Document Imaging | C27: DOC_REPO | D27: DOCUMENT | E27: DOC_DATE | F27: Document Date | G27: Date document was created | H27: DATE | I27: 10 | J27: Yes | K27: Valid date | L27: 45991 | M27: Internal | N27: Some missing dates | O27: Emily Davis
A28: SRC-0024 | B28: Legacy Servicing Platform | C28: SERVDB | D28: CUSTOMER | E28: MAILING_ADDR | F28: Mailing Address | H28: VARCHAR | I28: 100 | J28: Yes | K28: Valid address | L28: 456 Oak Ave | M28: PII | N28: Missing business definition | O28: Sarah Kim
A29: SRC-0025 | B29: Legacy Servicing Platform | C29: SERVDB | D29: CUSTOMER | E29: CUSTOMER_TYPE | F29: Customer Type | G29: Identifies borrower or co-borrower role | H29: VARCHAR | I29: 20 | J29: No | K29: Borrower, Co-Borrower | L29: Borrower | M29: NPI | O29: Sarah Kim
A30: SRC-0026 | B30: Legacy Servicing Platform | C30: SERVDB | D30: LOAN_MASTER | E30: MATURITY_DATE | F30: Maturity Date | G30: Date loan is scheduled to mature | H30: DATE | I30: 10 | J30: Yes | K30: Valid date | L30: 49461 | M30: Financial | N30: Validate against loan terms

Sheet Target Data Dictionary
A1: Target Data Dictionary
A2: Target platform metadata needed for mapping, transformation, testing, and migration build.
A4: Target Field ID | B4: Target Platform | C4: Target Entity/Object | D4: Target Field | E4: Business Name | F4: Target Definition | G4: Data Type | H4: Length | I4: Required? | J4: Allowed Values | K4: Default Value | L4: Create/Update Rule | M4: Data Sensitivity | N4: Owner/SME | O4: Notes
A5: TGT-0001 | B5: Modern Servicing Platform | C5: Loan | D5: servicingLoanId | E5: Servicing Loan ID | F5: Unique loan identifier in target servicing platform. | G5: String | H5: 20 | I5: Yes | L5: Created during boarding/migration | M5: NPI | N5: Sarah Kim
A6: TGT-0002 | B6: Modern Servicing Platform | C6: LoanBalance | D6: unpaidPrincipalBalance | E6: Unpaid Principal Balance | F6: Current UPB stored on target loan balance record. | G6: Decimal | H6: 18,2 | I6: Yes | L6: Loaded from approved balance source | M6: Confidential | N6: Jessica Lee
A7: TGT-0003 | B7: Modern Servicing Platform | C7: PaymentTransaction | D7: transactionType | E7: Payment Transaction Type | F7: Target normalized transaction category. | G7: String | H7: 30 | I7: Yes | J7: Payment, Reversal, Fee, Escrow | L7: Mapped using crosswalk | M7: Internal | N7: Michael Chen
A9: TGT-0004 | B9: Modern Servicing Platform | C9: Borrower | D9: borrowerID | E9: Borrower ID | F9: Unique borrower identifier | G9: String | H9: 15 | I9: Yes | J9: Unique | L9: Created during migration | M9: NPI | N9: Sarah Kim
A10: TGT-0005 | B10: Modern Servicing Platform | C10: Borrower | D10: firstName | E10: First Name | F10: Borrower first name | G10: String | H10: 50 | I10: Yes | J10: Alphabetic | L10: Loaded from source | M10: PII | N10: Sarah Kim
A11: TGT-0006 | B11: Modern Servicing Platform | C11: Borrower | D11: lastName | E11: Last Name | F11: Borrower last name | G11: String | H11: 50 | I11: Yes | J11: Alphabetic | L11: Loaded from source | M11: PII | N11: Sarah Kim
A12: TGT-0007 | B12: Modern Servicing Platform | C12: Borrower | D12: dateOfBirth | E12: Date of Birth | F12: Borrower birth date | G12: Date | H12: 10 | I12: No | J12: Valid date | L12: Converted from source | M12: PII | N12: Sarah Kim
A13: TGT-0008 | B13: Modern Servicing Platform | C13: Borrower | D13: emailAddress | E13: Email Address | F13: Borrower email | G13: String | H13: 100 | I13: No | J13: Valid email | L13: Loaded if available | M13: PII | N13: Sarah Kim
A14: TGT-0009 | B14: Modern Servicing Platform | C14: Borrower | D14: phoneNumber | E14: Phone Number | F14: Borrower phone | G14: String | H14: 15 | I14: No | J14: Valid phone | L14: Standardized during load | M14: PII | N14: Sarah Kim
A15: TGT-0010 | B15: Modern Servicing Platform | C15: Loan | D15: loanStatus | E15: Loan Status | F15: Current servicing status | G15: String | H15: 20 | I15: Yes | J15: Active, Closed, Delinquent | K15: Active | L15: Mapped using crosswalk | M15: Internal | N15: Sarah Kim
A16: TGT-0011 | B16: Modern Servicing Platform | C16: Loan | D16: interestRate | E16: Interest Rate | F16: Current interest rate | G16: Decimal | H16: 5,2 | I16: Yes | J16: Positive decimal | L16: Loaded from source | M16: Financial | N16: Jessica Lee
A17: TGT-0012 | B17: Modern Servicing Platform | C17: Escrow | D17: escrowBalance | E17: Escrow Balance | F17: Current escrow balance | G17: Decimal | H17: 18,2 | I17: No | J17: Positive decimal | K17: 0 | L17: Loaded from source | M17: Financial | N17: Jessica Lee
A18: TGT-0013 | B18: Modern Servicing Platform | C18: Property | D18: propertyAddress | E18: Property Address | F18: Street address | G18: String | H18: 100 | I18: Yes | J18: Valid address | L18: Loaded from source | M18: PII | N18: James Patel
A19: TGT-0014 | B19: Modern Servicing Platform | C19: Property | D19: city | E19: City | F19: Property city | G19: String | H19: 50 | I19: Yes | J19: Valid city | L19: Loaded from source | M19: Internal | N19: James Patel
A20: TGT-0015 | B20: Modern Servicing Platform | C20: Property | D20: stateCode | E20: State Code | F20: Two-letter state code | G20: String | H20: 2 | I20: Yes | J20: US state abbreviations | L20: Converted from source | M20: Internal | N20: James Patel
A21: TGT-0016 | B21: Modern Servicing Platform | C21: Property | D21: zipCode | E21: ZIP Code | F21: Property ZIP code | G21: String | H21: 10 | I21: Yes | J21: Valid ZIP | L21: Loaded from source | M21: Internal | N21: James Patel
A22: TGT-0017 | B22: Modern Servicing Platform | C22: Payment | D22: paymentDate | E22: Payment Date | F22: Date payment posted | G22: Date | H22: 10 | I22: Yes | J22: Valid date | L22: Loaded from source | M22: Financial | N22: Michael Chen
A23: TGT-0018 | B23: Modern Servicing Platform | C23: Payment | D23: paymentAmount | E23: Payment Amount | F23: Amount received | G23: Decimal | H23: 18,2 | I23: Yes | J23: Positive decimal | L23: Loaded from source | M23: Financial | N23: Michael Chen
A24: TGT-0019 | B24: Modern Servicing Platform | C24: Payment | D24: paymentMethod | E24: Payment Method | F24: Standard payment method | G24: String | H24: 20 | I24: No | J24: ACH, Check, Card | K24: ACH | L24: Mapped using lookup | M24: Internal | N24: Michael Chen
A25: TGT-0020 | B25: Modern Servicing Platform | C25: Payment | D25: reversalFlag | E25: Reversal Flag | F25: Indicates reversed payment | G25: String | H25: 1 | I25: Yes | J25: Y,N | K25: N | L25: Loaded from source | M25: Internal | N25: Michael Chen
A26: TGT-0021 | B26: Modern Servicing Platform | C26: Document | D26: documentID | E26: Document ID | F26: Unique document identifier | G26: String | H26: 30 | I26: Yes | J26: Unique | L26: Created during migration | M26: NPI | N26: Emily Davis
A27: TGT-0022 | B27: Modern Servicing Platform | C27: Document | D27: documentType | E27: Document Type | F27: Standard document classification | G27: String | H27: 30 | I27: Yes | J27: Statement, Notice, Letter | L27: Mapped using lookup | M27: Internal | N27: Emily Davis
A28: TGT-0023 | B28: Modern Servicing Platform | C28: Document | D28: documentDate | E28: Document Date | F28: Document creation date | G28: Date | H28: 10 | I28: No | J28: Valid date | L28: Loaded from source | M28: Internal | N28: Emily Davis
A29: TGT-0024 | B29: Modern Servicing Platform | C29: Borrower | D29: mailingAddress | E29: Mailing Address | F29: Borrower mailing address | G29: String | H29: 100 | I29: No | J29: Valid address | L29: Loaded from source | M29: PII | N29: Sarah Kim
A30: TGT-0025 | B30: Modern Servicing Platform | C30: Borrower | D30: customerRole | E30: Customer Role | F30: Borrower or Co-Borrower | G30: String | H30: 20 | I30: Yes | J30: Borrower, Co-Borrower | K30: Borrower | L30: Mapped from source | M30: Internal | N30: Sarah Kim
A31: TGT-0026 | B31: Modern Servicing Platform | C31: Loan | D31: maturityDate | E31: Maturity Date | F31: Scheduled loan maturity date | G31: Date | H31: 10 | I31: No | J31: Valid date | L31: Loaded from source | M31: Financial | N31: Sarah Kim

Sheet Business Glossary
A1: Business Glossary
A2: Common servicing terminology to align business meaning across legacy, target, reporting, and operations.
A4: Glossary Term ID | B4: Business Term | C4: Domain | D4: Business Definition | E4: Synonyms / Legacy Terms | F4: Authoritative Source | G4: Owner/Steward | H4: Approval Status | I4: Last Reviewed | J4: Notes
A5: TERM-0001 | B5: Unpaid Principal Balance | C5: Loan | D5: Outstanding principal balance owed by borrower excluding interest, fees, and escrow. | E5: UPB, Principal Balance | F5: Servicing policy / investor reporting | G5: Sarah Kim | H5: Approved | I5: 46204 | J5: Confirm investor-specific reporting usage
A6: TERM-0002 | B6: Suspense Balance | C6: Payment | D6: Funds received but not fully applied to the loan due to incomplete or exception processing. | E6: Suspense, Unapplied Funds | F6: Payment operations | G6: Michael Chen | H6: Approved | I6: 46204 | J6: High risk for migration reconciliation
A7: TERM-0003 | B7: Days Past Due | C7: Default | D7: Number of days a loan is past contractual due date based on servicing rules. | E7: DPD, Delinquency Days | F7: Default management policy | G7: Olivia Brown | H7: In Review | I7: 46204 | J7: Confirm target calculation
A9: TERM-0004 | B9: Escrow Balance | C9: Escrow | D9: Funds held to pay taxes and insurance on behalf of the borrower. | E9: Escrow Account | F9: Escrow Policy | G9: Jessica Lee | H9: Approved | I9: 46204 | J9: Validate during reconciliation
A10: TERM-0005 | B10: Loan Number | C10: Loan | D10: Unique identifier assigned to each mortgage loan. | E10: Loan ID | F10: Servicing System | G10: Sarah Kim | H10: Approved | I10: 46204 | J10: Primary loan key
A11: TERM-0006 | B11: Borrower | C11: Customer | D11: Individual responsible for repaying the mortgage loan. | E11: Customer, Mortgagor | F11: Loan Documentation | G11: Sarah Kim | H11: Approved | I11: 46204 | J11: Primary customer entity
A12: TERM-0007 | B12: Co-Borrower | C12: Customer | D12: Additional individual jointly responsible for the loan. | E12: Joint Borrower | F12: Loan Documentation | G12: Sarah Kim | H12: Approved | I12: 46204 | J12: May have separate contact information
A13: TERM-0008 | B13: Interest Rate | C13: Loan | D13: Annual interest percentage charged on the loan balance. | E13: Rate | F13: Loan Terms | G13: Jessica Lee | H13: Approved | I13: 46204 | J13: Stored as decimal value
A14: TERM-0009 | B14: Payment Date | C14: Payment | D14: Date a borrower payment is received and posted. | E14: Posting Date | F14: Payment Operations | G14: Michael Chen | H14: Approved | I14: 46204 | J14: Used in reconciliation
A15: TERM-0010 | B15: Payment Amount | C15: Payment | D15: Dollar amount received from the borrower. | E15: Payment | F15: Payment Operations | G15: Michael Chen | H15: Approved | I15: 46204 | J15: Must reconcile with transactions
A16: TERM-0011 | B16: Delinquency Status | C16: Default | D16: Current stage of loan delinquency based on servicing rules. | E16: Default Status | F16: Default Management Policy | G16: Olivia Brown | H16: Draft | I16: 46204 | J16: Verify target values
A17: TERM-0012 | B17: Maturity Date | C17: Loan | D17: Scheduled date when the loan should be fully repaid. | E17: Loan End Date | F17: Loan Agreement | G17: Sarah Kim | H17: Approved | I17: 46204 | J17: Compare with loan term
... A25: TERM-0020 | B25: Transaction Code | C25: Payment | D25: Code identifying the type of payment transaction. | E25: TXN Code | F25: Payment Operations | G25: Michael Chen | H25: Approved | I25: 46204 | J25: Mapped using code crosswalk

Sheet Critical Data Elements
A1: Critical Data Elements
A2: Prioritized high-risk servicing data requiring stronger controls, validation, and signoff.
A4: CDE ID | B4: Business Term | C4: Domain | D4: Source Field ID | E4: Target Field ID | F4: Why Critical | G4: Criticality Tier | H4: Data Sensitivity | I4: Regulatory / Financial Impact | J4: DQ Rule ID | K4: Reconciliation Rule ID | L4: Status | M4: Owner/Steward | N4: Notes
A5: CDE-0001 | B5: Servicing Loan ID | C5: Loan | D5: SRC-0001 | E5: TGT-0001 | F5: Primary key for migration, reconciliation, and servicing continuity. | G5: Tier 1 | H5: NPI | I5: Operational and regulatory | J5: DQ-0001 | K5: REC-0001 | L5: Approved | M5: Sarah Kim
A6: CDE-0002 | B6: Unpaid Principal Balance | C6: Loan | D6: SRC-0002 | E6: TGT-0002 | F6: Financial balance must reconcile before cutover. | G6: Tier 1 | H6: Confidential | I6: Financial, investor reporting | J6: DQ-0002 | K6: REC-0002 | L6: Approved | M6: Jessica Lee
A7: CDE-0003 | B7: Payment Transaction Type | C7: Payment | D7: SRC-0003 | E7: TGT-0003 | F7: Drives correct payment application history and customer/investor reporting. | G7: Tier 1 | H7: Internal | I7: Financial and customer impact | J7: DQ-0003 | K7: REC-0003 | L7: In Review | M7: Michael Chen
A9: CDE-0004 | B9: Customer ID | C9: Customer | D9: SRC-0004 | E9: TGT-0004 | F9: Unique customer identifier used across servicing platform. | G9: Tier 1 | H9: NPI | I9: Operational | J9: DQ-0004 | K9: REC-0004 | L9: Approved | M9: Sarah Kim | N9: Validate uniqueness
A10: CDE-0005 | B10: Loan Status | C10: Loan | D10: SRC-0010 | E10: TGT-0010 | F10: Determines servicing workflow and reporting. | G10: Tier 1 | H10: Internal | I10: Operational | J10: DQ-0005 | K10: REC-0005 | L10: In Review | M10: Sarah Kim | N10: Validate status mapping
A11: CDE-0006 | B11: Interest Rate | C11: Loan | D11: SRC-0011 | E11: TGT-0011 | F11: Used for payment calculations. | G11: Tier 1 | H11: Financial | I11: Financial | J11: DQ-0006 | K11: REC-0006 | L11: Approved | M11: Jessica Lee | N11: Precision validation
A12: CDE-0007 | B12: Escrow Balance | C12: Escrow | D12: SRC-0012 | E12: TGT-0012 | F12: Required for escrow reconciliation. | G12: Tier 1 | H12: Financial | I12: Financial | J12: DQ-0007 | K12: REC-0007 | L12: Approved | M12: Jessica Lee | N12: Must reconcile after migration
A13: CDE-0008 | B13: Property Address | C13: Property | D13: SRC-0013 | E13: TGT-0013 | F13: Required to identify collateral. | G13: Tier 2 | H13: PII | I13: Operational | J13: DQ-0008 | K13: REC-0008 | L13: Approved | M13: James Patel | N13: Address standardization required
A14: CDE-0009 | B14: Payment Date | C14: Payment | D14: SRC-0017 | E14: TGT-0016 | F14: Determines payment posting sequence. | G14: Tier 1 | H14: Financial | I14: Financial | J14: DQ-0009 | K14: REC-0009 | L14: Approved | M14: Michael Chen | N14: Cannot be future dated
A15: CDE-0010 | B15: Payment Amount | C15: Payment | D15: SRC-0018 | E15: TGT-0017 | F15: Used for balance reconciliation. | G15: Tier 1 | H15: Financial | I15: Financial | J15: DQ-0010 | K15: REC-0010 | L15: Approved | M15: Michael Chen | N15: Must equal source totals
A16: CDE-0011 | B16: Document ID | C16: Document | D16: SRC-0021 | E16: TGT-0020 | F16: Maintains document traceability after migration. | G16: Tier 2 | H16: NPI | I16: Compliance | J16: DQ-0011 | K16: REC-0011 | L16: Draft | M16: Emily Davis | N16: Verify document linkage
A17: CDE-0012 | B17: Maturity Date | C17: Loan | D17: SRC-0026 | E17: TGT-0025 | F17: Required for loan servicing lifecycle. | G17: Tier 2 | H17: Financial | I17: Financial | J17: DQ-0012 | K17: REC-0012 | L17: In Review | M17: Sarah Kim | N17: Validate against loan term

Sheet Source-to-Target Mapping
A1: Source-to-Target Mapping
A2: Core migration mapping matrix. Each row links to transformation, data quality, reconciliation, issue, and signoff evidence.
A4: Mapping ID | B4: Source System | C4: Source Table/Object | D4: Source Field | E4: Source Definition | F4: Target Platform | G4: Target Entity/Object | H4: Target Field | I4: Target Definition | J4: Mapping Type | K4: Transformation Rule ID | L4: DQ Rule ID | M4: Reconciliation Rule ID | N4: Data Domain | O4: Criticality Tier | P4: Data Sensitivity | Q4: Mapping Status | R4: SME Owner | S4: Tech Owner | T4: Issue ID | U4: Notes
A5: SERV-MAP-0001 | B5: Legacy Servicing Platform | C5: LOAN_MASTER | D5: LOAN_NBR | E5: Primary servicing loan identifier. | F5: Modern Servicing Platform | G5: Loan | H5: servicingLoanId | I5: Unique loan identifier in target. | J5: Direct | L5: DQ-0001 | M5: REC-0001 | N5: Loan | O5: Tier 1 | P5: NPI | Q5: Approved | R5: Sarah Kim | S5: Alex Johnson
A6: SERV-MAP-0002 | B6: Legacy Servicing Platform | C6: LOAN_BALANCE | D6: UPB_AMT | E6: Current unpaid principal balance. | F6: Modern Servicing Platform | G6: LoanBalance | H6: unpaidPrincipalBalance | I6: Current UPB in target. | J6: Direct | L6: DQ-0002 | M6: REC-0002 | N6: Loan | O6: Tier 1 | P6: Confidential | Q6: Approved | R6: Jessica Lee | S6: Alex Johnson
A7: SERV-MAP-0003 | B7: Legacy Servicing Platform | C7: PAYMENT_TXN | D7: TXN_CD | E7: Legacy payment transaction code. | F7: Modern Servicing Platform | G7: PaymentTransaction | H7: transactionType | I7: Normalized target transaction type. | J7: Lookup | K7: TR-0001 | L7: DQ-0003 | M7: REC-0003 | N7: Payment | O7: Tier 1 | P7: Internal | Q7: In Review | R7: Michael Chen | S7: David Brown | T7: ISS-0001 | U7: Requires code crosswalk approval
A9: SERV-MAP-0004 | B9: SRC-0004 | C9: CUSTOMER | D9: CUST_ID | E9: Customer identifier | F9: Modern Servicing Platform | G9: Borrower | H9: borrowerID | I9: Unique borrower identifier | J9: Direct | K9: TR-001 | L9: DQ-004 | M9: REC-004 | N9: Customer | O9: Tier 1 | P9: NPI | Q9: Approved | R9: Sarah Kim | S9: Alex Johnson
A10: SERV-MAP-0005 | B10: SRC-0005 | C10: CUSTOMER | D10: FIRST_NAME | E10: Borrower first name | F10: Modern Servicing Platform | G10: Borrower | H10: firstName | I10: First name | J10: Direct | K10: TR-002 | L10: DQ-005 | M10: REC-005 | N10: Customer | O10: Tier 2 | P10: PII | Q10: Approved | R10: Sarah Kim | S10: Alex Johnson
A11: SERV-MAP-0006 | B11: SRC-0006 | C11: CUSTOMER | D11: LAST_NAME | E11: Borrower last name | F11: Modern Servicing Platform | G11: Borrower | H11: lastName | I11: Last name | J11: Direct | K11: TR-003 | L11: DQ-006 | M11: REC-006 | N11: Customer | O11: Tier 2 | P11: PII | Q11: Approved | R11: Sarah Kim | S11: Alex Johnson
A12: SERV-MAP-0007 | B12: SRC-0007 | C12: CUSTOMER | D12: DOB | E12: Date of birth | F12: Modern Servicing Platform | G12: Borrower | H12: dateOfBirth | I12: Date of birth | J12: Transform | L12: DQ-007 | M12: REC-007 | N12: Customer | O12: Tier 2 | P12: PII | Q12: Open | R12: Sarah Kim | S12: Alex Johnson | T12: ISS-002 | U12: Missing transformation rule
A13: SERV-MAP-0008 | B13: SRC-0008 | C13: CUSTOMER | D13: EMAIL | E13: Email address | F13: Modern Servicing Platform | G13: Borrower | I13: Email address | J13: Direct | K13: TR-005 | L13: DQ-008 | M13: REC-008 | N13: Customer | O13: Tier 2 | P13: PII | Q13: Open | R13: Sarah Kim | S13: Alex Johnson | T13: ISS-003 | U13: Missing target field
A14: SERV-MAP-0009 | B14: SRC-0009 | C14: CUSTOMER | D14: PHONE | E14: Phone number | F14: Modern Servicing Platform | G14: Borrower | H14: phoneNumber | I14: Phone number | J14: Transform | K14: Standardize phone format | L14: DQ-009 | M14: REC-009 | N14: Customer | O14: Tier 2 | P14: PII | Q14: In Review | R14: Sarah Kim | S14: Alex Johnson
A15: SERV-MAP-0010 | B15: SRC-0010 | C15: LOAN_MASTER | D15: LOAN_STATUS | E15: Loan status | F15: Modern Servicing Platform | G15: Loan | H15: loanStatus | I15: Standard loan status | J15: Lookup | K15: Status Crosswalk | L15: DQ-010 | M15: REC-010 | N15: Loan | O15: Tier 1 | P15: Internal | Q15: Approved | R15: Sarah Kim | S15: David Brown
A16: SERV-MAP-0011 | B16: SRC-0011 | C16: LOAN_MASTER | D16: INTEREST_RATE | E16: Interest rate | F16: Modern Servicing Platform | G16: Loan | H16: interestRate | I16: Interest rate | J16: Direct | K16: TR-011 | L16: DQ-011 | M16: REC-011 | N16: Loan | O16: Tier 1 | P16: Financial | Q16: Approved | R16: Jessica Lee | S16: David Brown
A17: SERV-MAP-0012 | B17: SRC-0012 | C17: ESCROW | D17: ESCROW_BAL | E17: Escrow balance | F17: Modern Servicing Platform | G17: Escrow | H17: escrowBalance | I17: Escrow balance | J17: Direct | K17: TR-012 | L17: DQ-012 | M17: REC-012 | N17: Escrow | O17: Tier 1 | P17: Financial | Q17: Approved | R17: Jessica Lee | S17: David Brown
A18: SERV-MAP-0013 | B18: SRC-0013 | C18: PROPERTY | D18: PROPERTY_ADDR | E18: Property address | F18: Modern Servicing Platform | G18: Property | H18: propertyAddress | I18: Property address | J18: Direct | K18: TR-013 | L18: DQ-013 | M18: REC-013 | N18: Property | O18: Tier 2 | P18: PII | Q18: Approved | R18: James Patel | S18: David Brown
A19: SERV-MAP-0014 | B19: SRC-0013 | C19: PROPERTY | D19: PROPERTY_ADDR | E19: Property address | F19: Modern Servicing Platform | G19: Property | H19: propertyAddress | I19: Property address | J19: Direct | K19: TR-013 | L19: DQ-013 | M19: REC-013 | N19: Property | O19: Tier 2 | P19: PII | Q19: Approved | R19: James Patel | S19: David Brown | U19: Duplicate mapping
A20: SERV-MAP-0015 | B20: SRC-0017 | C20: PAYMENT_TXN | D20: PAYMENT_DATE | E20: Payment date | F20: Modern Servicing Platform | G20: Payment | H20: paymentDate | I20: Payment date | J20: Direct | K20: TR-015 | L20: DQ-015 | M20: REC-015 | N20: Payment | O20: Tier 1 | P20: Financial | Q20: Approved | R20: Michael Chen | S20: David Brown
A21: SERV-MAP-0016 | B21: SRC-0018 | C21: PAYMENT_TXN | D21: PAYMENT_AMT | E21: Payment amount | F21: Modern Servicing Platform | G21: Payment | H21: paymentAmount | I21: Payment amount | J21: Direct | K21: TR-016 | L21: DQ-016 | M21: REC-016 | N21: Payment | O21: Tier 1 | P21: Financial | Q21: Approved | R21: Michael Chen | S21: David Brown
A22: SERV-MAP-0017 | B22: SRC-0026 | C22: LOAN_MASTER | D22: MATURITY_DATE | E22: Loan maturity date | F22: Modern Servicing Platform | G22: Loan | H22: maturityDate | I22: Loan maturity date | J22: Direct | K22: TR-017 | L22: DQ-017 | M22: REC-017 | N22: Loan | O22: Tier 2 | P22: Financial | S22: David Brown | T22: ISS-005 | U22: Missing owner and status
A24: SERV-MAP-0018 | B24: SRC-0014 | C24: PROPERTY | D24: CITY | E24: Property city | F24: Modern Servicing Platform | G24: Property | H24: city | I24: Property city | J24: Direct | K24: TR-018 | L24: DQ-018 | M24: REC-018 | N24: Property | O24: Tier 2 | P24: Internal | Q24: Approved | R24: James Patel | S24: David Brown
A25: SERV-MAP-0019 | B25: SRC-0015 | C25: PROPERTY | D25: STATE | E25: Property state | F25: Modern Servicing Platform | G25: Property | H25: stateCode | I25: Two-letter state code | J25: Transform | K25: Convert full state name to abbreviation | L25: DQ-019 | M25: REC-019 | N25: Property | O25: Tier 2 | P25: Internal | Q25: Approved | R25: James Patel | S25: David Brown
A26: SERV-MAP-0020 | B26: SRC-0016 | C26: PROPERTY | D26: ZIP_CODE | E26: ZIP code | F26: Modern Servicing Platform | G26: Property | H26: zipCode | I26: ZIP code | J26: Direct | K26: TR-020 | L26: DQ-020 | M26: REC-020 | N26: Property | O26: Tier 2 | P26: Internal | Q26: Approved | R26: James Patel | S26: David Brown
A27: SERV-MAP-0021 | B27: SRC-0019 | C27: PAYMENT_TXN | D27: PAYMENT_METHOD | E27: Payment method | F27: Modern Servicing Platform | G27: Payment | H27: paymentMethod | I27: Payment method | J27: Lookup | K27: Payment Method Crosswalk | L27: DQ-021 | M27: REC-021 | N27: Payment | O27: Tier 2 | P27: Internal | Q27: Approved | R27: Michael Chen | S27: David Brown
A28: SERV-MAP-0022 | B28: SRC-0020 | C28: PAYMENT_TXN | D28: REVERSAL_IND | E28: Reversal indicator | F28: Modern Servicing Platform | G28: Payment | H28: reversalFlag | I28: Payment reversal flag | J28: Transform | K28: Convert Y/N values | L28: DQ-022 | M28: REC-022 | N28: Payment | O28: Tier 2 | P28: Internal | Q28: Approved | R28: Michael Chen | S28: David Brown
A29: SERV-MAP-0023 | B29: SRC-0021 | C29: DOCUMENT | D29: DOC_ID | E29: Document ID | F29: Modern Servicing Platform | G29: Document | H29: documentID | I29: Document identifier | J29: Direct | K29: TR-023 | L29: DQ-023 | M29: REC-023 | N29: Document | O29: Tier 2 | P29: NPI | Q29: Approved | R29: Emily Davis | S29: David Brown
A30: SERV-MAP-0024 | B30: SRC-0022 | C30: DOCUMENT | D30: DOC_TYPE | E30: Document type | F30: Modern Servicing Platform | G30: Document | H30: documentType | I30: Document classification | J30: Lookup | K30: Document Type Crosswalk | L30: DQ-024 | M30: REC-024 | N30: Document | O30: Tier 2 | P30: Internal | Q30: Approved | R30: Emily Davis | S30: David Brown
A31: SERV-MAP-0025 | B31: SRC-0023 | C31: DOCUMENT | D31: DOC_DATE | E31: Document date | F31: Modern Servicing Platform | G31: Document | H31: documentDate | I31: Document creation date | J31: Direct | K31: TR-025 | L31: DQ-025 | M31: REC-025 | N31: Document | O31: Tier 2 | P31: Internal | Q31: Approved | R31: Emily Davis | S31: David Brown
A32: SERV-MAP-0026 | B32: SRC-0024 | C32: CUSTOMER | D32: MAILING_ADDR | E32: Mailing address | F32: Modern Servicing Platform | G32: Borrower | H32: mailingAddress | I32: Borrower mailing address | J32: Direct | K32: TR-026 | L32: DQ-026 | M32: REC-026 | N32: Customer | O32: Tier 2 | P32: PII | Q32: In Review | R32: Sarah Kim | S32: Alex Johnson | U32: Validate address standardization
A33: SERV-MAP-0027 | B33: SRC-0025 | C33: CUSTOMER | D33: CUSTOMER_TYPE | E33: Customer role | F33: Modern Servicing Platform | G33: Borrower | H33: customerRole | I33: Borrower role | J33: Lookup | K33: Customer Role Crosswalk | L33: DQ-027 | M33: REC-027 | N33: Customer | O33: Tier 2 | P33: Internal | Q33: Approved | R33: Sarah Kim | S33: Alex Johnson
A34: SERV-MAP-0028 | B34: SRC-0008 | C34: CUSTOMER | D34: EMAIL | E34: Email address | F34: Modern Servicing Platform | G34: Borrower | H34: emailAddress | I34: Borrower email | J34: Direct | K34: TR-028 | M34: REC-028 | N34: Customer | O34: Tier 2 | P34: PII | Q34: In Review | R34: Sarah Kim | S34: Alex Johnson | T34: ISS-006 | U34: Missing DQ Rule
A35: SERV-MAP-0029 | B35: SRC-0010 | C35: LOAN_MASTER | D35: LOAN_STATUS | E35: Loan status | F35: Modern Servicing Platform | G35: Loan | H35: loanStatus | I35: Loan status | J35: Lookup | K35: Status Crosswalk | L35: DQ-029 | N35: Loan | O35: Tier 1 | P35: Internal | Q35: Approved | R35: Sarah Kim | S35: David Brown | T35: ISS-007 | U35: Missing reconciliation rule
A36: SERV-MAP-0030 | B36: SRC-0015 | C36: PROPERTY | D36: STATE | E36: Property state | F36: Modern Servicing Platform | G36: Property | H36: stateCode | I36: State code | J36: Direct | K36: TR-030 | L36: DQ-030 | M36: REC-030 | N36: Property | O36: Tier 2 | P36: Internal | Q36: Approved | R36: James Patel | S36: David Brown | T36: ISS-008 | U36: Mapping type should probably be Transform
A37: SERV-MAP-0031 | B37: SRC-0005 | C37: CUSTOMER | D37: FIRST_NAME | E37: First name | F37: Modern Servicing Platform | G37: Borrower | H37: firstName | I37: First name | J37: Direct | K37: TR-031 | L37: DQ-031 | M37: REC-031 | N37: Customer | O37: Tier 2 | P37: PII | Q37: Approved | R37: Sarah Kim | S37: Alex Johnson
A38: SERV-MAP-0032 | B38: SRC-0006 | C38: CUSTOMER | D38: LAST_NAME | E38: Last name | F38: Modern Servicing Platform | G38: Borrower | H38: lastName | I38: Last name | J38: Direct | K38: TR-032 | L38: DQ-032 | M38: REC-032 | N38: Customer | O38: Tier 2 | P38: PII | Q38: Approved | R38: Sarah Kim | S38: Alex Johnson

Sheet Transformation Rules
A1: Transformation Rules
A2: Reusable conversion, derivation, defaulting, formatting, survivorship, and lookup rules.
A4: Rule ID | B4: Rule Name | C4: Rule Type | D4: Description | E4: Input Fields | F4: Output Field | G4: Business Logic / Formula | H4: Default / Exception Handling | I4: Owner | J4: Approval Status | K4: Related Mapping IDs | L4: Notes
A6: TR-001 | B6: Transaction Code Crosswalk | C6: Lookup | D6: Convert legacy transaction codes to target values | E6: PAYMENT_TXN.TXN_CD | F6: Payment.transactionType | G6: Use lookup table to convert codes | H6: Invalid code → review | I6: Michael Chen | J6: Approved | K6: SERV-MAP-0003
A7: TR-002 | B7: First Name Copy | C7: Direct | D7: Copy first name | E7: CUSTOMER.FIRST_NAME | F7: Borrower.firstName | G7: Copy as-is | H7: Blank allowed | I7: Sarah Kim | J7: Approved | K7: SERV-MAP-0005
A8: TR-003 | B8: Last Name Copy | C8: Direct | D8: Copy last name | E8: CUSTOMER.LAST_NAME | F8: Borrower.lastName | G8: Copy as-is | H8: Blank allowed | I8: Sarah Kim | J8: Approved | K8: SERV-MAP-0006
A9: TR-004 | B9: Customer ID Copy | C9: Direct | D9: Copy customer ID | E9: CUSTOMER.CUST_ID | F9: Borrower.borrowerID | G9: Copy as-is | H9: Must be unique | I9: Sarah Kim | J9: Approved | K9: SERV-MAP-0004
A10: TR-005 | B10: Email Validation | C10: Validation | D10: Validate email format | E10: CUSTOMER.EMAIL | F10: Borrower.emailAddress | G10: Check email pattern | H10: Invalid email → review | I10: Sarah Kim | J10: Draft | K10: SERV-MAP-0008
A11: TR-006 | B11: Phone Formatting | C11: Transform | D11: Standardize phone numbers | E11: CUSTOMER.PHONE | F11: Borrower.phoneNumber | G11: Remove symbols and format | H11: Invalid phone → review | I11: Sarah Kim | J11: Approved | K11: SERV-MAP-0009
A12: TR-007 | B12: DOB Conversion | C12: Transform | D12: Convert DOB to target date format | E12: CUSTOMER.DOB | F12: Borrower.dateOfBirth | G12: YYYYMMDD → MM/DD/YYYY | H12: Invalid date → reject | I12: Sarah Kim | J12: In Review | K12: SERV-MAP-0007
A13: TR-008 | B13: Loan Status Lookup | C13: Lookup | D13: Convert loan status | E13: LOAN_MASTER.LOAN_STATUS | F13: Loan.loanStatus | G13: Use status crosswalk | H13: Unknown → Pending Review | I13: Sarah Kim | J13: Approved | K13: SERV-MAP-0010
A14: TR-009 | B14: Interest Rate Copy | C14: Direct | D14: Copy interest rate | E14: LOAN_MASTER.INTEREST_RATE | F14: Loan.interestRate | G14: Copy value | H14: Null allowed | I14: Jessica Lee | J14: Approved | K14: SERV-MAP-0011
A15: TR-010 | B15: Escrow Balance Copy | C15: Direct | D15: Copy escrow balance | E15: ESCROW.ESCROW_BAL | F15: Escrow.escrowBalance | G15: Copy value | H15: Null = 0 | I15: Jessica Lee | J15: Approved | K15: SERV-MAP-0012
A16: TR-011 | B16: Property Address Copy | C16: Direct | D16: Copy address | E16: PROPERTY.PROPERTY_ADDR | F16: Property.propertyAddress | G16: Copy as-is | H16: Trim spaces | I16: James Patel | J16: Approved | K16: SERV-MAP-0013
A17: TR-012 | B17: City Copy | C17: Direct | D17: Copy city | E17: PROPERTY.CITY | F17: Property.city | G17: Copy as-is | H17: Trim spaces | I17: James Patel | J17: Approved | K17: SERV-MAP-0018
... A25: TR-020 | B25: Maturity Date Copy | C25: Direct | D25: Copy maturity date | E25: LOAN_MASTER.MATURITY_DATE | F25: Loan.maturityDate | G25: Copy value | H25: Validate date | I25: Sarah Kim | J25: Approved | K25: SERV-MAP-0017

Sheet Code Lookup Crosswalk
A1: Code Lookup Crosswalk
A2: Legacy-to-target value mapping for payment, delinquency, default, investor, escrow, fee, and status codes.
A4: Crosswalk ID | B4: Crosswalk Type | C4: Source System | D4: Source Code | E4: Source Description | F4: Target Platform | G4: Target Code | H4: Target Description | I4: Effective Date | J4: End Date | K4: Approval Status | L4: Owner | M4: Notes
A6: CW-0001 | B6: Payment Transaction Code | C6: Legacy Servicing Platform | D6: PMT | E6: Regular payment | F6: Modern Servicing Platform | G6: Payment | H6: Borrower payment received | I6: 46204 | K6: Approved | L6: Michael Chen
A7: CW-0002 | B7: Payment Transaction Code | C7: Legacy Servicing Platform | D7: REV | E7: Payment reversal | F7: Modern Servicing Platform | G7: Reversal | H7: Payment reversal transaction | I7: 46204 | K7: Approved | L7: Michael Chen
A8: CW-0003 | B8: Payment Transaction Code | C8: Legacy Servicing Platform | D8: FEE | E8: Fee payment | F8: Modern Servicing Platform | G8: Fee | H8: Fee transaction | I8: 46204 | K8: Approved | L8: Michael Chen
A9: CW-0004 | B9: Loan Status | C9: Legacy Servicing Platform | D9: ACT | E9: Active loan | F9: Modern Servicing Platform | G9: Active | H9: Active servicing loan | I9: 46204 | K9: Approved | L9: Sarah Kim
A10: CW-0005 | B10: Loan Status | C10: Legacy Servicing Platform | D10: CLS | E10: Closed loan | F10: Modern Servicing Platform | G10: Closed | H10: Closed servicing loan | I10: 46204 | K10: Approved | L10: Sarah Kim
A11: CW-0006 | B11: Loan Status | C11: Legacy Servicing Platform | D11: DEL | E11: Delinquent loan | F11: Modern Servicing Platform | G11: Delinquent | H11: Past due loan | I11: 46204 | K11: Approved | L11: Sarah Kim
A12: CW-0007 | B12: State Code | C12: Legacy Servicing Platform | D12: Florida | E12: Full state name | F12: Modern Servicing Platform | G12: FL | H12: Florida | I12: 46204 | K12: Approved | L12: James Patel | M12: Used in address conversion
A13: CW-0008 | B13: State Code | C13: Legacy Servicing Platform | D13: Texas | E13: Full state name | F13: Modern Servicing Platform | G13: TX | H13: Texas | I13: 46204 | K13: Approved | L13: James Patel
A14: CW-0009 | B14: Customer Role | C14: Legacy Servicing Platform | D14: BOR | E14: Borrower | F14: Modern Servicing Platform | G14: Borrower | H14: Primary borrower | I14: 46204 | K14: Approved | L14: Sarah Kim
A15: CW-0010 | B15: Customer Role | C15: Legacy Servicing Platform | D15: COB | E15: Co-Borrower | F15: Modern Servicing Platform | G15: CoBorrower | H15: Secondary borrower | I15: 46204 | K15: Approved | L15: Sarah Kim
A16: CW-0011 | B16: Payment Method | C16: Legacy Servicing Platform | D16: ACH | E16: Electronic payment | F16: Modern Servicing Platform | G16: ACH | H16: Automated Clearing House | I16: 46204 | K16: Approved | L16: Michael Chen
A17: CW-0012 | B17: Payment Method | C17: Legacy Servicing Platform | D17: CHK | E17: Paper check | F17: Modern Servicing Platform | G17: Check | H17: Check payment | I17: 46204 | K17: Draft | L17: Michael Chen | M17: Verify legacy payment code

Sheet Data Quality Rules
A1: Data Quality Rules
A2: Validation rules supporting migration build, testing, exception management, and cutover certification.
A4: DQ Rule ID | B4: Rule Name | C4: Rule Type | D4: Data Domain | E4: Target Field / Entity | F4: Rule Description | G4: Severity | H4: Expected Result | I4: Exception Handling | J4: Related Mapping IDs | K4: Owner | L4: Status | M4: Notes
A6: DQ-0001 | B6: Loan ID Required | C6: Required | D6: Loan | E6: Loan.servicingLoanId | F6: Loan ID must not be blank | G6: High | H6: No null values | I6: Reject record | J6: SERV-MAP-0001 | K6: Sarah Kim | L6: Approved | M6: Primary key
A7: DQ-0002 | B7: UPB Balance Check | C7: Range | D7: Loan | E7: LoanBalance.unpaidPrincipalBalance | F7: Balance must be ≥ 0 | G7: High | H7: No negative balances | I7: Review exception | J7: SERV-MAP-0002 | K7: Jessica Lee | L7: Approved | M7: Financial validation
A8: DQ-0003 | B8: Transaction Type Valid | C8: Valid Value | D8: Payment | E8: Payment.transactionType | F8: Value must exist in lookup | G8: High | H8: Valid code only | I8: Review invalid codes | J8: SERV-MAP-0003 | K8: Michael Chen | L8: Approved
A9: DQ-0004 | B9: Customer ID Unique | C9: Uniqueness | D9: Customer | E9: Borrower.borrowerID | F9: Customer IDs must be unique | G9: High | H9: No duplicates | I9: Investigate duplicates | J9: SERV-MAP-0004 | K9: Sarah Kim | L9: Approved
A10: DQ-0005 | B10: First Name Required | C10: Required | D10: Customer | E10: Borrower.firstName | F10: First name cannot be blank | G10: Medium | H10: Value populated | I10: Flag missing value | J10: SERV-MAP-0005 | K10: Sarah Kim | L10: Approved
A11: DQ-0006 | B11: Last Name Required | C11: Required | D11: Customer | E11: Borrower.lastName | F11: Last name cannot be blank | G11: Medium | H11: Value populated | I11: Flag missing value | J11: SERV-MAP-0006 | K11: Sarah Kim | L11: Approved
A12: DQ-0007 | B12: DOB Valid Date | C12: Format | D12: Customer | E12: Borrower.dateOfBirth | F12: DOB must be valid date | G12: High | H12: Correct format | I12: Reject invalid dates | J12: SERV-MAP-0007 | K12: Sarah Kim | L12: In Review
A13: DQ-0008 | B13: Email Format | C13: Format | D13: Customer | E13: Borrower.emailAddress | F13: Email must contain @ | G13: Medium | H13: Valid email | I13: Flag invalid email | J13: SERV-MAP-0008 | K13: Sarah Kim | L13: Draft
A14: DQ-0009 | B14: Phone Format | C14: Format | D14: Customer | E14: Borrower.phoneNumber | F14: Phone formatted as XXX-XXX-XXXX | G14: Medium | H14: Standard format | I14: Standardize value | J14: SERV-MAP-0009 | K14: Sarah Kim | L14: Approved
A15: DQ-0010 | B15: Loan Status Valid | C15: Valid Value | D15: Loan | E15: Loan.loanStatus | F15: Must exist in status lookup | G15: High | H15: Approved value | I15: Review invalid status | J15: SERV-MAP-0010 | K15: Sarah Kim | L15: Approved
A16: DQ-0011 | B16: Interest Rate Range | C16: Range | D16: Loan | E16: Loan.interestRate | F16: Rate between 0% and 25% | G16: Medium | H16: Valid percentage | I16: Flag outliers | J16: SERV-MAP-0011 | K16: Jessica Lee | L16: Approved
A17: DQ-0012 | B17: Escrow Balance Check | C17: Range | D17: Escrow | E17: Escrow.escrowBalance | F17: Balance cannot be negative | G17: Medium | H17: ≥ 0 | I17: Review exception | J17: SERV-MAP-0012 | K17: Jessica Lee | L17: Approved

Sheet Reconciliation Rules
A1: Reconciliation Rules
A2: Controls that prove migrated data is complete, accurate, and ready for business certification.
A4: Recon Rule ID | B4: Rule Name | C4: Recon Type | D4: Data Domain | E4: Source Basis | F4: Target Basis | G4: Reconciliation Logic | H4: Tolerance | I4: Frequency | J4: Evidence Location | K4: Owner | L4: Status | M4: Related Mapping IDs | N4: Notes
A6: REC-0004 | B6: Customer Record Count | C6: Count | D6: Customer | E6: Legacy CUSTOMER table | F6: Borrower table | G6: Compare total borrower records | H6: 0 difference | I6: Each test cycle | J6: Sarah Kim | K6: Approved | L6: SERV-MAP-0004
A7: REC-0005 | B7: Escrow Balance | C7: Balance | D7: Escrow | E7: Escrow balances | F7: Escrow balances | G7: Compare escrow balances by loan | H7: ±$0.01 | I7: Each cycle | J7: Jessica Lee | K7: Approved | L7: SERV-MAP-0012
A8: REC-0006 | B8: Interest Rate | C8: Field Value | D8: Loan | E8: Interest rate | F8: Interest rate | G8: Compare rate to 5 decimals | H8: Exact match | I8: Each cycle | J8: Jessica Lee | K8: Approved | L8: SERV-MAP-0011
A9: REC-0007 | B9: Loan Status | C9: Value | D9: Loan | E9: Loan status | F9: Loan status | G9: Validate status crosswalk | H9: Exact match | I9: Each cycle | J9: Sarah Kim | K9: Approved | L9: SERV-MAP-0010
A10: REC-0008 | B10: Property Address | C10: Field Value | D10: Property | E10: Property address | F10: Property address | G10: Compare normalized addresses | H10: Exact match | I10: Each cycle | J10: James Patel | K10: Approved | L10: SERV-MAP-0013 | M10: Standardize abbreviations first
A11: REC-0009 | B11: Payment Date | C11: Field Value | D11: Payment | E11: Payment date | F11: Payment date | G11: Dates must match | H11: Exact match | I11: Each cycle | J11: Michael Chen | K11: Approved | L11: SERV-MAP-0015
A12: REC-0010 | B12: Maturity Date | C12: Field Value | D12: Loan | E12: Loan maturity | F12: Loan maturity | G12: Verify maturity date transferred | H12: Exact match | I12: Cutover | J12: Sarah Kim | K12: Draft | L12: SERV-MAP-0017 | M12: Final validation before go-live

Sheet Issues Decisions Log
A1: Issues Decisions Log
A2: Single place to track open questions, assumptions, decisions, risks, and approvals.
A4: Log ID | B4: Type | C4: Title | D4: Description | E4: Data Domain | F4: Severity | G4: Owner | H4: Due Date | I4: Status | J4: Decision / Resolution | K4: Business Rationale | L4: Approved By | M4: Approval Date | N4: Related Mapping IDs
A6: ISS-0001 | B6: Issue | C6: Payment code crosswalk not approved | D6: Legacy payment transaction code mapping requires SME validation. | E6: Payment | F6: High | G6: Michael Chen | H6: 46213 | I6: Open | J6: Pending business approval | K6: Required before payment migration can begin. | N6: SERV-MAP-0003
A7: DEC-0001 | B7: Decision | C7: Migrate 24 months of payment history | D7: Business elected to migrate only the most recent payment history. | E7: Payment | F7: Medium | G7: Michael Chen | H7: 46215 | I7: Approved | J7: Migrate last 24 months only. | K7: Reduces migration effort while meeting business needs. | L7: Sarah Kim | M7: 46214 | N7: SERV-MAP-0015, SERV-MAP-0016
A8: ISS-0002 | B8: Issue | C8: Missing DOB transformation rule | D8: Date of birth requires formatting before loading target system. | E8: Customer | F8: Medium | G8: Sarah Kim | H8: 46216 | I8: In Progress | J8: Create TR-0007 transformation rule. | K8: Prevent invalid date formats. | N8: SERV-MAP-0007
A9: ISS-0003 | B9: Issue | C9: Missing target email field | D9: Target email attribute has not been finalized. | E9: Customer | F9: Medium | G9: Sarah Kim | H9: 46217 | I9: Open | J9: Await target model update. | K9: Prevent incorrect customer contact migration. | N9: SERV-MAP-0008
A10: DEC-0002 | B10: Decision | C10: Standardize phone number format | D10: All phone numbers will follow a common format. | E10: Customer | F10: Low | G10: Sarah Kim | H10: 46214 | I10: Approved | J10: Convert to ###-###-#### format. | K10: Improves downstream integrations. | L10: Alex Johnson | M10: 46214 | N10: SERV-MAP-0009
A11: ISS-0004 | B11: Issue | C11: Duplicate property mapping | D11: Duplicate Property Address mapping identified during review. | E11: Property | F11: Medium | G11: James Patel | H11: 46218 | I11: Closed | J11: Duplicate removed from mapping inventory. | K11: Prevent duplicate migration logic. | L11: James Patel | M11: 46218 | N11: SERV-MAP-0014
A12: DEC-0003 | B12: Decision | C12: State code conversion | D12: Property state values will use USPS abbreviations. | E12: Property | F12: Low | G12: James Patel | H12: 46213 | I12: Approved | J12: Apply state lookup crosswalk. | K12: Standardize reporting and validation. | L12: Sarah Kim | M12: 46213 | N12: SERV-MAP-0019
A13: ISS-0005 | B13: Issue | C13: Missing reconciliation rule | D13: Loan Status mapping lacks reconciliation verification. | E13: Loan | F13: High | G13: Sarah Kim | H13: 46219 | I13: Open | J13: Create REC-0029 before UAT. | K13: Required for production signoff. | N13: SERV-MAP-0029
A14: DEC-0004 | B14: Decision | C14: Escrow balance tolerance | D14: Balance reconciliation tolerance established. | E14: Escrow | F14: Medium | G14: Jessica Lee | H14: 46213 | I14: Approved | J14: Allow ±$0.01 difference. | K14: Accounts for rounding differences. | L14: Jessica Lee | M14: 46213 | N14: SERV-MAP-0012
A15: ISS-0006 | B15: Issue | C15: Missing mapping owner | D15: Loan maturity mapping has no assigned SME owner. | E15: Loan | F15: Medium | G15: Sarah Kim | H15: 46220 | I15: In Progress | J15: Assign Sarah Kim as business owner. | K15: Required before final signoff. | N15: SERV-MAP-0017
A16: DEC-0005 | B16: Decision | C16: Customer role mapping | D16: Borrower and Co-Borrower values standardized. | E16: Customer | F16: Low | G16: Sarah Kim | H16: 46215 | I16: Approved | J16: Use customer role lookup table. | K16: Consistent target values. | L16: Alex Johnson | M16: 46215 | N16: SERV-MAP-0027
A17: ISS-0007 | B17: Issue | C17: Payment method lookup incomplete | D17: Legacy payment method codes CHK and ACH verified; Wire still missing. | E17: Payment | F17: Medium | G17: Michael Chen | H17: 46221 | I17: Open | J17: Complete lookup crosswalk. | K17: Prevent unmapped payment methods. | N17: SERV-MAP-0021

Sheet Signoff Tracker
A1: Signoff Tracker
A2: Approval tracking for mapping packages, critical data elements, rules, reconciliation, and cutover readiness.
